Traceback (most recent call last):
  File "/Users/kashnitsky/Library/Caches/pypoetry/virtualenvs/mlcourse-ai-L-dGjTF0-py3.12/lib/python3.12/site-packages/jupyter_cache/executors/utils.py", line 58, in single_nb_execution
    executenb(
  File "/Users/kashnitsky/Library/Caches/pypoetry/virtualenvs/mlcourse-ai-L-dGjTF0-py3.12/lib/python3.12/site-packages/nbclient/client.py", line 1305, in execute
    return NotebookClient(nb=nb, resources=resources, km=km, **kwargs).execute()
           ^^^^^^^^^^^^^^^^^^^^^^^^^^^^^^^^^^^^^^^^^^^^^^^^^^^^^^^^^^^^^^^^^^^^^
  File "/Users/kashnitsky/Library/Caches/pypoetry/virtualenvs/mlcourse-ai-L-dGjTF0-py3.12/lib/python3.12/site-packages/jupyter_core/utils/__init__.py", line 165, in wrapped
    return loop.run_until_complete(inner)
           ^^^^^^^^^^^^^^^^^^^^^^^^^^^^^^
  File "/opt/homebrew/Cellar/python@3.12/3.12.7_1/Frameworks/Python.framework/Versions/3.12/lib/python3.12/asyncio/base_events.py", line 687, in run_until_complete
    return future.result()
           ^^^^^^^^^^^^^^^
  File "/Users/kashnitsky/Library/Caches/pypoetry/virtualenvs/mlcourse-ai-L-dGjTF0-py3.12/lib/python3.12/site-packages/nbclient/client.py", line 705, in async_execute
    await self.async_execute_cell(
  File "/Users/kashnitsky/Library/Caches/pypoetry/virtualenvs/mlcourse-ai-L-dGjTF0-py3.12/lib/python3.12/site-packages/nbclient/client.py", line 1058, in async_execute_cell
    await self._check_raise_for_error(cell, cell_index, exec_reply)
  File "/Users/kashnitsky/Library/Caches/pypoetry/virtualenvs/mlcourse-ai-L-dGjTF0-py3.12/lib/python3.12/site-packages/nbclient/client.py", line 914, in _check_raise_for_error
    raise CellExecutionError.from_cell_and_msg(cell, exec_reply_content)
nbclient.exceptions.CellExecutionError: An error occurred while executing the following cell:
------------------
plotSARIMA(ads, best_model, 50)
------------------


[0;31m---------------------------------------------------------------------------[0m
[0;31mAttributeError[0m                            Traceback (most recent call last)
[0;32m/var/folders/n0/1qj4_6k97ms4rnr_bsfq6j40018_cq/T/ipykernel_36977/2337694703.py[0m in [0;36m?[0;34m()[0m
[0;32m----> 1[0;31m [0mplotSARIMA[0m[0;34m([0m[0mads[0m[0;34m,[0m [0mbest_model[0m[0;34m,[0m [0;36m50[0m[0;34m)[0m[0;34m[0m[0;34m[0m[0m
[0m
[0;32m/var/folders/n0/1qj4_6k97ms4rnr_bsfq6j40018_cq/T/ipykernel_36977/3069305344.py[0m in [0;36m?[0;34m(series, model, n_steps)[0m
[1;32m     16[0m     [0mdata[0m[0;34m[[0m[0;34m"arima_model"[0m[0;34m][0m[0;34m[[0m[0;34m:[0m [0ms[0m [0;34m+[0m [0md[0m[0;34m][0m [0;34m=[0m [0mnp[0m[0;34m.[0m[0mnan[0m[0;34m[0m[0;34m[0m[0m
[1;32m     17[0m [0;34m[0m[0m
[1;32m     18[0m     [0;31m# forecasting on n_steps forward[0m[0;34m[0m[0;34m[0m[0m
[1;32m     19[0m     [0mforecast[0m [0;34m=[0m [0mmodel[0m[0;34m.[0m[0mpredict[0m[0;34m([0m[0mstart[0m[0;34m=[0m[0mdata[0m[0;34m.[0m[0mshape[0m[0;34m[[0m[0;36m0[0m[0;34m][0m[0;34m,[0m [0mend[0m[0;34m=[0m[0mdata[0m[0;34m.[0m[0mshape[0m[0;34m[[0m[0;36m0[0m[0;34m][0m [0;34m+[0m [0mn_steps[0m[0;34m)[0m[0;34m[0m[0;34m[0m[0m
[0;32m---> 20[0;31m     [0mforecast[0m [0;34m=[0m [0mdata[0m[0;34m.[0m[0marima_model[0m[0;34m.[0m[0mappend[0m[0;34m([0m[0mforecast[0m[0;34m)[0m[0;34m[0m[0;34m[0m[0m
[0m[1;32m     21[0m     [0;31m# calculate error, again having shifted on s+d steps from the beginning[0m[0;34m[0m[0;34m[0m[0m
[1;32m     22[0m     error = mean_absolute_percentage_error(
[1;32m     23[0m         [0mdata[0m[0;34m[[0m[0;34m"actual"[0m[0;34m][0m[0;34m[[0m[0ms[0m [0;34m+[0m [0md[0m [0;34m:[0m[0;34m][0m[0;34m,[0m [0mdata[0m[0;34m[[0m[0;34m"arima_model"[0m[0;34m][0m[0;34m[[0m[0ms[0m [0;34m+[0m [0md[0m [0;34m:[0m[0;34m][0m[0;34m[0m[0;34m[0m[0m

[0;32m~/Library/Caches/pypoetry/virtualenvs/mlcourse-ai-L-dGjTF0-py3.12/lib/python3.12/site-packages/pandas/core/generic.py[0m in [0;36m?[0;34m(self, name)[0m
[1;32m   6295[0m             [0;32mand[0m [0mname[0m [0;32mnot[0m [0;32min[0m [0mself[0m[0;34m.[0m[0m_accessors[0m[0;34m[0m[0;34m[0m[0m
[1;32m   6296[0m             [0;32mand[0m [0mself[0m[0;34m.[0m[0m_info_axis[0m[0;34m.[0m[0m_can_hold_identifiers_and_holds_name[0m[0;34m([0m[0mname[0m[0;34m)[0m[0;34m[0m[0;34m[0m[0m
[1;32m   6297[0m         [0;34m)[0m[0;34m:[0m[0;34m[0m[0;34m[0m[0m
[1;32m   6298[0m             [0;32mreturn[0m [0mself[0m[0;34m[[0m[0mname[0m[0;34m][0m[0;34m[0m[0;34m[0m[0m
[0;32m-> 6299[0;31m         [0;32mreturn[0m [0mobject[0m[0;34m.[0m[0m__getattribute__[0m[0;34m([0m[0mself[0m[0;34m,[0m [0mname[0m[0;34m)[0m[0;34m[0m[0;34m[0m[0m
[0m
[0;31mAttributeError[0m: 'Series' object has no attribute 'append'

